<?xml version="1.0" ?>
  
  <sdf version="1.5">
    <model name="arduwoodpecker_claw">
      
      <include>
        <uri>model://arduwoodpecker_claw_base</uri>
        <name>arduwoodpecker_claw_base</name>
        <pose>0 0 0.0 0 0 0</pose>
      </include>
      <!----------------------------------------->
      <include>
        <uri>model://arduwoodpecker_claw_flange</uri>
        <name>arduwoodpecker_claw_flange</name>
        <pose>0.00078 0 -0.0124 0 0 0</pose>
      </include>
      <joint name="arduwoodpecker_claw_flange_joint" type="fixed">
      <!--  <joint name="arduwoodpecker_claw_flange_joint" type="prismatic">-->
          <parent>arduwoodpecker_claw_base::claw_base</parent>
          <child>arduwoodpecker_claw_flange::claw_flange</child>
          <axis>
            <limit>
              <upper>0.0</upper>
              <lower>-0.9</lower>
            </limit>
            <xyz>0 0 1</xyz>
          </axis>
        </joint>
        <!----------------------------------------->
        <!----------------------------------------->
        <include>
          <uri>model://arduwoodpecker_claw_pole</uri>
          <name>arduwoodpecker_claw_pole_0</name>
          <pose>0 -0.0195 -0.0124 -0.26563911215353697 0 0</pose>
        </include>
        <joint name="arduwoodpecker_claw_pole_0_joint" type="revolute">
          <parent>arduwoodpecker_claw_flange::claw_flange</parent>
          <child>arduwoodpecker_claw_pole_0::claw_pole</child>
          <pose>0 0 0 0 0 0</pose>
          <axis>
            <xyz>1 0 0</xyz>
            <limit>
              <lower>-1.5707963267948966</lower>
              <upper>1.5707963267948966</upper>
            </limit>
          </axis>
          <dynamics>
            <damping>0.004</damping>
          </dynamics>
          <use_parent_model_frame>1</use_parent_model_frame>
          <physics>
            <ode>
              <implicit_spring_damper>1</implicit_spring_damper>
            </ode>
          </physics>
        </joint>
        <!----------------------------------------->
        <!----------------------------------------->
        <include>
          <uri>model://arduwoodpecker_claw_pole</uri>
          <name>arduwoodpecker_claw_pole_1</name>
          <pose>0 0.0195 -0.0124 0.26563911215353697 0 0</pose>
        </include>
        <joint name="arduwoodpecker_claw_pole_1_joint" type="revolute">
          <parent>arduwoodpecker_claw_flange::claw_flange</parent>
          <child>arduwoodpecker_claw_pole_1::claw_pole</child>
          <pose>0 0 0 0 0 0</pose>
          <axis>
            <xyz>1 0 0</xyz>
            <limit>
              <lower>-1.5707963267948966</lower>
              <upper>1.5707963267948966</upper>
            </limit>
          </axis>
          <dynamics>
            <damping>0.004</damping>
          </dynamics>
          <use_parent_model_frame>1</use_parent_model_frame>
          <physics>
            <ode>
              <implicit_spring_damper>1</implicit_spring_damper>
            </ode>
          </physics>
        </joint>
        <!----------------------------------------->
        <!----------------------------------------->
        <include>
          <uri>model://arduwoodpecker_claw_hand</uri>
          <name>arduwoodpecker_claw_hand_0</name>
          <pose>0 -0.031 -0.05 0 0 0</pose>
        </include>
        <joint name="arduwoodpecker_claw_hand_0_joint" type="revolute">
          <parent>arduwoodpecker_claw_pole_0::claw_pole</parent>
          <child>arduwoodpecker_claw_hand_0::claw_hand</child>
          <pose>0 0 0 0 0 0</pose>
          <axis>
            <xyz>1 0 0</xyz>
            <limit>
              <lower>-1.5707963267948966</lower>
              <upper>1.5707963267948966</upper>
            </limit>
          </axis>
          <dynamics>
            <damping>0.004</damping>
          </dynamics>
          <use_parent_model_frame>1</use_parent_model_frame>
          <physics>
            <ode>
              <implicit_spring_damper>1</implicit_spring_damper>
            </ode>
          </physics>
        </joint>
        <joint name="arduwoodpecker_claw_hand_0_1_joint" type="revolute">
          <parent>arduwoodpecker_claw_base::claw_base</parent>
          <child>arduwoodpecker_claw_hand_0::claw_hand</child>
          <pose>0 0 -0.04 0 0 0</pose>
          <axis>
            <xyz>1 0 0</xyz>
            <limit>
              <lower>-1.5707963267948966</lower>
              <upper>1.5707963267948966</upper>
            </limit>
          </axis>
          <dynamics>
            <damping>0.004</damping>
          </dynamics>
          <use_parent_model_frame>1</use_parent_model_frame>
          <physics>
            <ode>
              <implicit_spring_damper>1</implicit_spring_damper>
            </ode>
          </physics>
        </joint>
        <!----------------------------------------->
        <!----------------------------------------->
        <include>
          <uri>model://arduwoodpecker_claw_hand</uri>
          <name>arduwoodpecker_claw_hand_1</name>
          <pose>0 0.031 -0.05 0 0 3.141592653589793</pose>
        </include>
        <joint name="arduwoodpecker_claw_hand_1_joint" type="revolute">
          <parent>arduwoodpecker_claw_pole_1::claw_pole</parent>
          <child>arduwoodpecker_claw_hand_1::claw_hand</child>
          <axis>
            <xyz>1 0 0</xyz>
            <limit>
              <lower>-1.5707963267948966</lower>
              <upper>1.5707963267948966</upper>
            </limit>
          </axis>
          <dynamics>
            <damping>0.004</damping>
          </dynamics>
          <use_parent_model_frame>1</use_parent_model_frame>
          <physics>
            <ode>
              <implicit_spring_damper>1</implicit_spring_damper>
            </ode>
          </physics>
        </joint>
        <joint name="arduwoodpecker_claw_hand_1_1_joint" type="revolute">
          <parent>arduwoodpecker_claw_base::claw_base</parent>
          <child>arduwoodpecker_claw_hand_1::claw_hand</child>
          <pose>0 0 -0.04 0 0 0</pose>
          <axis>
            <xyz>1 0 0</xyz>
            <limit>
              <lower>-1.5707963267948966</lower>
              <upper>1.5707963267948966</upper>
            </limit>
          </axis>
          <dynamics>
            <damping>0.004</damping>
          </dynamics>
          <use_parent_model_frame>1</use_parent_model_frame>
          <physics>
            <ode>
              <implicit_spring_damper>1</implicit_spring_damper>
            </ode>
          </physics>
        </joint>
        <!----------------------------------------->
        <!----------------------------------------->
      </model>
    </sdf>
