<?xml version="1.0" ?>
  
  <sdf version="1.5">
    <model name="tsduav_t4_multi">
      <self_collide>0</self_collide>
      
      <include>
        <uri>model://tsduav_t4_multi_base</uri>
        <name>tsduav_t4_multi_base</name>
        <pose>0 0 0.0 0 0 0</pose>
      </include>
      
      <include>
        <uri>model://tsduav_t4_multi_prop</uri>
        <name>tsduav_t4_multi_prop_0</name>
        <pose>0.53541 -1.00941 0.0775 0 0 0</pose>
      </include>
      <joint name="tsduav_t4_multi_prop_0_joint" type="revolute">
        <parent>tsduav_t4_multi_base::base</parent>
        <child>tsduav_t4_multi_prop_0::prop </child>
        <axis>
          <xyz>0 0 1</xyz>
          <limit>
            <lower>-1e+16</lower>
            <upper>1e+16</upper>
          </limit>
          <dynamics>
            <damping>0.00001</damping>
          </dynamics>
          <use_parent_model_frame>1</use_parent_model_frame>
        </axis>
      </joint>
    
      <include>
        <uri>model://tsduav_t4_multi_prop</uri>
        <name>tsduav_t4_multi_prop_1</name>
        <pose>0.53541 -1.00941 -0.0975 0 0 0</pose>
      </include>
      <joint name="tsduav_t4_multi_prop_1_joint" type="revolute">
        <parent>tsduav_t4_multi_base::base</parent>
        <child>tsduav_t4_multi_prop_1::prop </child>
        <axis>
          <xyz>0 0 1</xyz>
          <limit>
            <lower>-1e+16</lower>
            <upper>1e+16</upper>
          </limit>
          <dynamics>
            <damping>0.00001</damping>
          </dynamics>
          <use_parent_model_frame>1</use_parent_model_frame>
        </axis>
      </joint>
    
      <include>
        <uri>model://tsduav_t4_multi_prop</uri>
        <name>tsduav_t4_multi_prop_2</name>
        <pose>-0.53541 -1.00941 0.0775 0 0 0</pose>
      </include>
      <joint name="tsduav_t4_multi_prop_2_joint" type="revolute">
        <parent>tsduav_t4_multi_base::base</parent>
        <child>tsduav_t4_multi_prop_2::prop </child>
        <axis>
          <xyz>0 0 1</xyz>
          <limit>
            <lower>-1e+16</lower>
            <upper>1e+16</upper>
          </limit>
          <dynamics>
            <damping>0.00001</damping>
          </dynamics>
          <use_parent_model_frame>1</use_parent_model_frame>
        </axis>
      </joint>
    
      <include>
        <uri>model://tsduav_t4_multi_prop</uri>
        <name>tsduav_t4_multi_prop_3</name>
        <pose>-0.53541 -1.00941 -0.0975 0 0 0</pose>
      </include>
      <joint name="tsduav_t4_multi_prop_3_joint" type="revolute">
        <parent>tsduav_t4_multi_base::base</parent>
        <child>tsduav_t4_multi_prop_3::prop </child>
        <axis>
          <xyz>0 0 1</xyz>
          <limit>
            <lower>-1e+16</lower>
            <upper>1e+16</upper>
          </limit>
          <dynamics>
            <damping>0.00001</damping>
          </dynamics>
          <use_parent_model_frame>1</use_parent_model_frame>
        </axis>
      </joint>
    
      <include>
        <uri>model://tsduav_t4_multi_prop</uri>
        <name>tsduav_t4_multi_prop_4</name>
        <pose>-0.53541 1.00941 0.0775 0 0 0</pose>
      </include>
      <joint name="tsduav_t4_multi_prop_4_joint" type="revolute">
        <parent>tsduav_t4_multi_base::base</parent>
        <child>tsduav_t4_multi_prop_4::prop </child>
        <axis>
          <xyz>0 0 1</xyz>
          <limit>
            <lower>-1e+16</lower>
            <upper>1e+16</upper>
          </limit>
          <dynamics>
            <damping>0.00001</damping>
          </dynamics>
          <use_parent_model_frame>1</use_parent_model_frame>
        </axis>
      </joint>
    
      <include>
        <uri>model://tsduav_t4_multi_prop</uri>
        <name>tsduav_t4_multi_prop_5</name>
        <pose>-0.53541 1.00941 -0.0975 0 0 0</pose>
      </include>
      <joint name="tsduav_t4_multi_prop_5_joint" type="revolute">
        <parent>tsduav_t4_multi_base::base</parent>
        <child>tsduav_t4_multi_prop_5::prop </child>
        <axis>
          <xyz>0 0 1</xyz>
          <limit>
            <lower>-1e+16</lower>
            <upper>1e+16</upper>
          </limit>
          <dynamics>
            <damping>0.00001</damping>
          </dynamics>
          <use_parent_model_frame>1</use_parent_model_frame>
        </axis>
      </joint>
    
      <include>
        <uri>model://tsduav_t4_multi_prop</uri>
        <name>tsduav_t4_multi_prop_6</name>
        <pose>0.53541 1.00941 0.0775 0 0 0</pose>
      </include>
      <joint name="tsduav_t4_multi_prop_6_joint" type="revolute">
        <parent>tsduav_t4_multi_base::base</parent>
        <child>tsduav_t4_multi_prop_6::prop </child>
        <axis>
          <xyz>0 0 1</xyz>
          <limit>
            <lower>-1e+16</lower>
            <upper>1e+16</upper>
          </limit>
          <dynamics>
            <damping>0.00001</damping>
          </dynamics>
          <use_parent_model_frame>1</use_parent_model_frame>
        </axis>
      </joint>
    
      <include>
        <uri>model://tsduav_t4_multi_prop</uri>
        <name>tsduav_t4_multi_prop_7</name>
        <pose>0.53541 1.00941 -0.0975 0 0 0</pose>
      </include>
      <joint name="tsduav_t4_multi_prop_7_joint" type="revolute">
        <parent>tsduav_t4_multi_base::base</parent>
        <child>tsduav_t4_multi_prop_7::prop </child>
        <axis>
          <xyz>0 0 1</xyz>
          <limit>
            <lower>-1e+16</lower>
            <upper>1e+16</upper>
          </limit>
          <dynamics>
            <damping>0.00001</damping>
          </dynamics>
          <use_parent_model_frame>1</use_parent_model_frame>
        </axis>
      </joint>
    
    <include>
      <uri>model://tsduav_t4_multi_link</uri>
      <name>tsduav_t4_multi_link</name>
      <pose>1.034 0 -0.226 0 -1.5707963267948966 0</pose>
    </include>
    <joint name='link_base_joint' type='revolute'>
      <parent>tsduav_t4_multi_link::link_base</parent>
      <child>tsduav_t4_multi_base::base</child>
      <pose>0 0 -0.226 0 -1.5707963267948966 0</pose>
      <axis>
          <xyz>0 -1 0</xyz>
          <limit>
            <lower>-3.141592653589793</lower>
            <upper>1.5707963267948966</upper>
          </limit>
          <dynamics>
            <damping>0.001</damping>
          </dynamics>
          <use_parent_model_frame>1</use_parent_model_frame>
        </axis>
    </joint>
    
    <include>
      <uri>model://tsduav_t4_multi_saw</uri>
      <name>tsduav_t4_multi_saw</name>
      <pose>1.6 0 -0.226 0 0 0</pose>
    </include>
    <joint name='tsduav_t4_multi_saw_1_joint' type='fixed'>
      <child>tsduav_t4_multi_saw::saw</child>
      <parent>tsduav_t4_multi_link::link_base</parent>
      <use_parent_model_frame>1</use_parent_model_frame>
    </joint>
  </model>
</sdf>
