<?xml version="1.0" ?>
  
  <sdf version="1.5">
    <model name="arduwoodpecker">
      

      <include>
        <uri>model://arduwoodpecker_platform</uri>
        <name>arduwoodpecker_platform</name>
        <pose>0 0 0.0 0 0 0</pose>
      </include>

      <include>
        <uri>model://arduwoodpecker_tiltrotor</uri>
        <name>arduwoodpecker_tiltrotor_0</name>
        <pose>0.251 -0.171 0 0 0 0</pose>
      </include>
      <include>
        <uri>model://arduwoodpecker_tiltrotor</uri>
        <name>arduwoodpecker_tiltrotor_1</name>
        <pose>-0.251 -0.171 0 0 0 0</pose>
      </include>
      <include>
        <uri>model://arduwoodpecker_tiltrotor</uri>
        <name>arduwoodpecker_tiltrotor_2</name>
        <pose>-0.251 0.171 0 0 0 3.141592653589793</pose>
      </include>
      <include>
        <uri>model://arduwoodpecker_tiltrotor</uri>
        <name>arduwoodpecker_tiltrotor_3</name>
        <pose>0.251 0.171 0 0 0 3.141592653589793</pose>
      </include>
      <joint name="arduwoodpecker_tiltrotor_0_joint" type="fixed">
        <parent>arduwoodpecker_platform::platform_base</parent>
        <child>arduwoodpecker_tiltrotor_0::tiltrotor_tube</child>
      </joint>
      <joint name="arduwoodpecker_tiltrotor_1_joint" type="fixed">
        <parent>arduwoodpecker_platform::platform_base</parent>
        <child>arduwoodpecker_tiltrotor_1::tiltrotor_tube</child>
      </joint>
      <joint name="arduwoodpecker_tiltrotor_2_joint" type="fixed">
        <parent>arduwoodpecker_platform::platform_base</parent>
        <child>arduwoodpecker_tiltrotor_2::tiltrotor_tube</child>
      </joint>
      <joint name="arduwoodpecker_tiltrotor_3_joint" type="fixed">
        <parent>arduwoodpecker_platform::platform_base</parent>
        <child>arduwoodpecker_tiltrotor_3::tiltrotor_tube</child>
      </joint>
      
      <plugin name="tiltrotor_0_plugin" filename='librotors_gazebo_motor_model.so'>
        <robotNamespace></robotNamespace>
        <jointName> arduwoodpecker_tiltrotor_0::tiltrotor_tilt_joint  </jointName>
        <linkName> arduwoodpecker_tiltrotor_0::tiltrotor_tilt </linkName>
        <turningDirection>cw</turningDirection>
        <motorType>position</motorType>
        <commandSubTopic>/gazebo/command/tilt_pos</commandSubTopic>
        <motorNumber>0</motorNumber>
        <motorSpeedPubTopic>tilt_pos/0</motorSpeedPubTopic>
        <joint_control_pid>
          <p>1.5</p>
          <i>0.001</i>
          <d>0.2</d>
          <iMax>2</iMax>
          <iMin>-2</iMin>
          <cmdMax>50</cmdMax>
          <cmdMin>-50</cmdMin>
        </joint_control_pid>
      </plugin>
    
      <plugin name="tiltrotor_1_plugin" filename='librotors_gazebo_motor_model.so'>
        <robotNamespace></robotNamespace>
        <jointName> arduwoodpecker_tiltrotor_1::tiltrotor_tilt_joint  </jointName>
        <linkName> arduwoodpecker_tiltrotor_1::tiltrotor_tilt </linkName>
        <turningDirection>cw</turningDirection>
        <motorType>position</motorType>
        <commandSubTopic>/gazebo/command/tilt_pos</commandSubTopic>
        <motorNumber>1</motorNumber>
        <motorSpeedPubTopic>tilt_pos/1</motorSpeedPubTopic>
        <joint_control_pid>
          <p>1.5</p>
          <i>0.001</i>
          <d>0.2</d>
          <iMax>2</iMax>
          <iMin>-2</iMin>
          <cmdMax>50</cmdMax>
          <cmdMin>-50</cmdMin>
        </joint_control_pid>
      </plugin>
    
      <plugin name="tiltrotor_2_plugin" filename='librotors_gazebo_motor_model.so'>
        <robotNamespace></robotNamespace>
        <jointName> arduwoodpecker_tiltrotor_2::tiltrotor_tilt_joint  </jointName>
        <linkName> arduwoodpecker_tiltrotor_2::tiltrotor_tilt </linkName>
        <turningDirection>cw</turningDirection>
        <motorType>position</motorType>
        <commandSubTopic>/gazebo/command/tilt_pos</commandSubTopic>
        <motorNumber>2</motorNumber>
        <motorSpeedPubTopic>tilt_pos/2</motorSpeedPubTopic>
        <joint_control_pid>
          <p>1.5</p>
          <i>0.001</i>
          <d>0.2</d>
          <iMax>2</iMax>
          <iMin>-2</iMin>
          <cmdMax>50</cmdMax>
          <cmdMin>-50</cmdMin>
        </joint_control_pid>
      </plugin>
    
      <plugin name="tiltrotor_3_plugin" filename='librotors_gazebo_motor_model.so'>
        <robotNamespace></robotNamespace>
        <jointName> arduwoodpecker_tiltrotor_3::tiltrotor_tilt_joint  </jointName>
        <linkName> arduwoodpecker_tiltrotor_3::tiltrotor_tilt </linkName>
        <turningDirection>cw</turningDirection>
        <motorType>position</motorType>
        <commandSubTopic>/gazebo/command/tilt_pos</commandSubTopic>
        <motorNumber>3</motorNumber>
        <motorSpeedPubTopic>tilt_pos/3</motorSpeedPubTopic>
        <joint_control_pid>
          <p>1.5</p>
          <i>0.001</i>
          <d>0.2</d>
          <iMax>2</iMax>
          <iMin>-2</iMin>
          <cmdMax>50</cmdMax>
          <cmdMin>-50</cmdMin>
        </joint_control_pid>
      </plugin>
    

    
    <include>
      <uri>model://arduwoodpecker_prop_ccw</uri>
      <name>arduwoodpecker_prop_0</name>
      <pose>0.251 -0.33025 0.070146 0.0 0 0</pose>
    </include>
    <include>
      <uri>model://arduwoodpecker_prop_cw</uri>
      <name>arduwoodpecker_prop_1</name>
      <pose>-0.251 -0.33025 0.070146 0.0 0 0</pose>
    </include>
    <include>
      <uri>model://arduwoodpecker_prop_ccw</uri>
      <name>arduwoodpecker_prop_2</name>
      <pose>-0.251 0.33025 0.070146 0.0 0 0</pose>
    </include>
    <include>
      <uri>model://arduwoodpecker_prop_cw</uri>
      <name>arduwoodpecker_prop_3</name>
      <pose>0.251 0.33025 0.070146 0.0 0 0</pose>
    </include>
    
    
    <joint name="prop_0_joint" type='revolute'>
      <child>arduwoodpecker_prop_0::prop</child>
      <parent>arduwoodpecker_tiltrotor_0::tiltrotor_tilt</parent>
      <axis>
        <xyz>0 0 1</xyz>
        <limit>
          <lower>-1e+16</lower>
          <upper>1e+16</upper>
        </limit>
        <dynamics>
          <damping>0.004</damping>
        </dynamics>
        <use_parent_model_frame>1</use_parent_model_frame>
      </axis>
      <physics>
        <ode>
          <implicit_spring_damper>1</implicit_spring_damper>
        </ode>
      </physics>
    </joint>
    <plugin name="prop_motor_0_plugin" filename='librotors_gazebo_motor_model.so'>
      <robotNamespace></robotNamespace>
      <jointName>prop_0_joint </jointName>
      <linkName>arduwoodpecker_prop_0::prop</linkName>
      <turningDirection>ccw</turningDirection>
      <timeConstantUp>0.0125</timeConstantUp>
      <timeConstantDown>0.025</timeConstantDown>
      <maxRotVelocity>1000</maxRotVelocity>
      <motorConstant>8.599e-05</motorConstant>
      <momentConstant>0.25</momentConstant>
      <commandSubTopic>/gazebo/command/prop_speed</commandSubTopic>
      <motorNumber>0</motorNumber>
      <rotorDragCoefficient>0.000806428</rotorDragCoefficient>
      <rollingMomentCoefficient>1e-06</rollingMomentCoefficient>
      <motorSpeedPubTopic>prop_speed/0</motorSpeedPubTopic>
      <rotorVelocitySlowdownSim>10</rotorVelocitySlowdownSim>
    </plugin>
  
    <joint name="prop_1_joint" type='revolute'>
      <child>arduwoodpecker_prop_1::prop</child>
      <parent>arduwoodpecker_tiltrotor_1::tiltrotor_tilt</parent>
      <axis>
        <xyz>0 0 1</xyz>
        <limit>
          <lower>-1e+16</lower>
          <upper>1e+16</upper>
        </limit>
        <dynamics>
          <damping>0.004</damping>
        </dynamics>
        <use_parent_model_frame>1</use_parent_model_frame>
      </axis>
      <physics>
        <ode>
          <implicit_spring_damper>1</implicit_spring_damper>
        </ode>
      </physics>
    </joint>
    <plugin name="prop_motor_1_plugin" filename='librotors_gazebo_motor_model.so'>
      <robotNamespace></robotNamespace>
      <jointName>prop_1_joint </jointName>
      <linkName>arduwoodpecker_prop_1::prop</linkName>
      <turningDirection>cw</turningDirection>
      <timeConstantUp>0.0125</timeConstantUp>
      <timeConstantDown>0.025</timeConstantDown>
      <maxRotVelocity>1000</maxRotVelocity>
      <motorConstant>8.599e-05</motorConstant>
      <momentConstant>0.25</momentConstant>
      <commandSubTopic>/gazebo/command/prop_speed</commandSubTopic>
      <motorNumber>1</motorNumber>
      <rotorDragCoefficient>0.000806428</rotorDragCoefficient>
      <rollingMomentCoefficient>1e-06</rollingMomentCoefficient>
      <motorSpeedPubTopic>prop_speed/1</motorSpeedPubTopic>
      <rotorVelocitySlowdownSim>10</rotorVelocitySlowdownSim>
    </plugin>
  
    <joint name="prop_2_joint" type='revolute'>
      <child>arduwoodpecker_prop_2::prop</child>
      <parent>arduwoodpecker_tiltrotor_2::tiltrotor_tilt</parent>
      <axis>
        <xyz>0 0 1</xyz>
        <limit>
          <lower>-1e+16</lower>
          <upper>1e+16</upper>
        </limit>
        <dynamics>
          <damping>0.004</damping>
        </dynamics>
        <use_parent_model_frame>1</use_parent_model_frame>
      </axis>
      <physics>
        <ode>
          <implicit_spring_damper>1</implicit_spring_damper>
        </ode>
      </physics>
    </joint>
    <plugin name="prop_motor_2_plugin" filename='librotors_gazebo_motor_model.so'>
      <robotNamespace></robotNamespace>
      <jointName>prop_2_joint </jointName>
      <linkName>arduwoodpecker_prop_2::prop</linkName>
      <turningDirection>ccw</turningDirection>
      <timeConstantUp>0.0125</timeConstantUp>
      <timeConstantDown>0.025</timeConstantDown>
      <maxRotVelocity>1000</maxRotVelocity>
      <motorConstant>8.599e-05</motorConstant>
      <momentConstant>0.25</momentConstant>
      <commandSubTopic>/gazebo/command/prop_speed</commandSubTopic>
      <motorNumber>2</motorNumber>
      <rotorDragCoefficient>0.000806428</rotorDragCoefficient>
      <rollingMomentCoefficient>1e-06</rollingMomentCoefficient>
      <motorSpeedPubTopic>prop_speed/2</motorSpeedPubTopic>
      <rotorVelocitySlowdownSim>10</rotorVelocitySlowdownSim>
    </plugin>
  
    <joint name="prop_3_joint" type='revolute'>
      <child>arduwoodpecker_prop_3::prop</child>
      <parent>arduwoodpecker_tiltrotor_3::tiltrotor_tilt</parent>
      <axis>
        <xyz>0 0 1</xyz>
        <limit>
          <lower>-1e+16</lower>
          <upper>1e+16</upper>
        </limit>
        <dynamics>
          <damping>0.004</damping>
        </dynamics>
        <use_parent_model_frame>1</use_parent_model_frame>
      </axis>
      <physics>
        <ode>
          <implicit_spring_damper>1</implicit_spring_damper>
        </ode>
      </physics>
    </joint>
    <plugin name="prop_motor_3_plugin" filename='librotors_gazebo_motor_model.so'>
      <robotNamespace></robotNamespace>
      <jointName>prop_3_joint </jointName>
      <linkName>arduwoodpecker_prop_3::prop</linkName>
      <turningDirection>cw</turningDirection>
      <timeConstantUp>0.0125</timeConstantUp>
      <timeConstantDown>0.025</timeConstantDown>
      <maxRotVelocity>1000</maxRotVelocity>
      <motorConstant>8.599e-05</motorConstant>
      <momentConstant>0.25</momentConstant>
      <commandSubTopic>/gazebo/command/prop_speed</commandSubTopic>
      <motorNumber>3</motorNumber>
      <rotorDragCoefficient>0.000806428</rotorDragCoefficient>
      <rollingMomentCoefficient>1e-06</rollingMomentCoefficient>
      <motorSpeedPubTopic>prop_speed/3</motorSpeedPubTopic>
      <rotorVelocitySlowdownSim>10</rotorVelocitySlowdownSim>
    </plugin>
  

  <plugin name="ArduRotorTiltPlugin" filename="libArduRotorTiltPlugin.so">
    <fdm_addr>127.0.0.1</fdm_addr>
    <fdm_port_in>9002</fdm_port_in>
    <fdm_port_out>9003</fdm_port_out>
    <modelXYZToAirplaneXForwardZDown>0 0 0 3.141593 0 0</modelXYZToAirplaneXForwardZDown>
    <gazeboXYZToNED>0 0 0 3.141593 0 0</gazeboXYZToNED>
    <motor_num>4</motor_num>
    <servo_num>4</servo_num>
    <motor_pub>/gazebo/command/prop_speed</motor_pub>
    <servo_pub>/gazebo/command/tilt_pos</servo_pub>
    <imuName>arduwoodpecker_platform::imu_link::imu_sensor</imuName>
    <connectionTimeoutMaxCount>5</connectionTimeoutMaxCount>
  </plugin>
  
  <!--
  <include>
    <uri>model://iwp_claw</uri>
    <name>iwp_claw_0</name>
    <pose>-0.17 -0.0 -0.0995 0 0 0</pose>
  </include>
  <include>
    <uri>model://iwp_claw</uri>
    <name>iwp_claw_1</name>
    <pose>0.17 0 -0.0995 0 0 0 0</pose>
  </include>
  <joint name="iwp_claw_0_joint" type="fixed">
    <parent>arduwoodpecker_platform::platform_base</parent>
    <child>iwp_claw_0::claw_base</child>
  </joint>
  <joint name="iwp_claw_1_joint" type="fixed">
    <parent>arduwoodpecker_platform::platform_base</parent>
    <child>iwp_claw_1::claw_base</child>
  </joint>
  
  <plugin name="position_control_0" filename="librotors_gazebo_position_control.so">
    <robotNamespace></robotNamespace>
    <jointName>iwp_claw_0::claw_flange_joint</jointName>
    <linkName>iwp_claw_0::claw_flange</linkName>
    <motorNumber>0</motorNumber>
    <commandSubTopic>/gazebo/command/flage_pos</commandSubTopic>
    <joint_control_pid>
      <p>10</p>
      <i>0.01</i>
      <d>5</d>
      <iMax>20</iMax>
      <iMin>-20</iMin>
      <cmdMax>100000</cmdMax>
      <cmdMin>-100000</cmdMin>
    </joint_control_pid>
  </plugin>
-->
</model>
</sdf>
