<?xml version="1.0" ?>
  
  <sdf version="1.5">
    <model name="tsduav_t4">
      <self_collide>0</self_collide>
      
      <include>
        <uri>model://tsduav_t4_base</uri>
        <name>tsduav_t4_base</name>
        <pose>0 0 0.0 0 0 0</pose>
      </include>
      
      <include>
        <uri>model://tsduav_t4_prop</uri>
        <name>tsduav_t4_prop_0</name>
        <pose>0.53541 -1.00941 0.0775 0 0 0</pose>
      </include>
      <joint name="tsduav_t4_prop_0_joint" type="revolute">
        <parent>tsduav_t4_base::base</parent>
        <child>tsduav_t4_prop_0::prop </child>
        <axis>
          <xyz>0 0 1</xyz>
          <limit>
            <lower>-1e+16</lower>
            <upper>1e+16</upper>
          </limit>
          <dynamics>
            <damping>0.00001</damping>
          </dynamics>
          <use_parent_model_frame>1</use_parent_model_frame>
        </axis>
      </joint>
      <plugin name="tsduav_t4_prop_0_plugin" filename='librotors_gazebo_motor_model.so'>
        <robotNamespace></robotNamespace>
        <jointName>tsduav_t4_prop_0_joint </jointName>
        <linkName>tsduav_t4_prop_0::prop</linkName>
        <turningDirection>ccw</turningDirection>
        <timeConstantUp>0.0125</timeConstantUp>
        <timeConstantDown>0.025</timeConstantDown>
        <maxRotVelocity>1000</maxRotVelocity>
        <motorConstant>8.599e-05</motorConstant>
        <momentConstant>0.25</momentConstant>
        <commandSubTopic>/gazebo/command/prop_speed</commandSubTopic>
        <motorNumber>0</motorNumber>
        <rotorDragCoefficient>0.000806428</rotorDragCoefficient>
        <rollingMomentCoefficient>1e-06</rollingMomentCoefficient>
        <motorSpeedPubTopic>prop_speed/0</motorSpeedPubTopic>
        <rotorVelocitySlowdownSim>10</rotorVelocitySlowdownSim>
      </plugin>
    
      <include>
        <uri>model://tsduav_t4_prop</uri>
        <name>tsduav_t4_prop_1</name>
        <pose>0.53541 -1.00941 -0.0975 0 0 0</pose>
      </include>
      <joint name="tsduav_t4_prop_1_joint" type="revolute">
        <parent>tsduav_t4_base::base</parent>
        <child>tsduav_t4_prop_1::prop </child>
        <axis>
          <xyz>0 0 1</xyz>
          <limit>
            <lower>-1e+16</lower>
            <upper>1e+16</upper>
          </limit>
          <dynamics>
            <damping>0.00001</damping>
          </dynamics>
          <use_parent_model_frame>1</use_parent_model_frame>
        </axis>
      </joint>
      <plugin name="tsduav_t4_prop_1_plugin" filename='librotors_gazebo_motor_model.so'>
        <robotNamespace></robotNamespace>
        <jointName>tsduav_t4_prop_1_joint </jointName>
        <linkName>tsduav_t4_prop_1::prop</linkName>
        <turningDirection>cw</turningDirection>
        <timeConstantUp>0.0125</timeConstantUp>
        <timeConstantDown>0.025</timeConstantDown>
        <maxRotVelocity>1000</maxRotVelocity>
        <motorConstant>8.599e-05</motorConstant>
        <momentConstant>0.25</momentConstant>
        <commandSubTopic>/gazebo/command/prop_speed</commandSubTopic>
        <motorNumber>1</motorNumber>
        <rotorDragCoefficient>0.000806428</rotorDragCoefficient>
        <rollingMomentCoefficient>1e-06</rollingMomentCoefficient>
        <motorSpeedPubTopic>prop_speed/1</motorSpeedPubTopic>
        <rotorVelocitySlowdownSim>10</rotorVelocitySlowdownSim>
      </plugin>
    
      <include>
        <uri>model://tsduav_t4_prop</uri>
        <name>tsduav_t4_prop_2</name>
        <pose>-0.53541 -1.00941 0.0775 0 0 0</pose>
      </include>
      <joint name="tsduav_t4_prop_2_joint" type="revolute">
        <parent>tsduav_t4_base::base</parent>
        <child>tsduav_t4_prop_2::prop </child>
        <axis>
          <xyz>0 0 1</xyz>
          <limit>
            <lower>-1e+16</lower>
            <upper>1e+16</upper>
          </limit>
          <dynamics>
            <damping>0.00001</damping>
          </dynamics>
          <use_parent_model_frame>1</use_parent_model_frame>
        </axis>
      </joint>
      <plugin name="tsduav_t4_prop_2_plugin" filename='librotors_gazebo_motor_model.so'>
        <robotNamespace></robotNamespace>
        <jointName>tsduav_t4_prop_2_joint </jointName>
        <linkName>tsduav_t4_prop_2::prop</linkName>
        <turningDirection>cw</turningDirection>
        <timeConstantUp>0.0125</timeConstantUp>
        <timeConstantDown>0.025</timeConstantDown>
        <maxRotVelocity>1000</maxRotVelocity>
        <motorConstant>8.599e-05</motorConstant>
        <momentConstant>0.25</momentConstant>
        <commandSubTopic>/gazebo/command/prop_speed</commandSubTopic>
        <motorNumber>2</motorNumber>
        <rotorDragCoefficient>0.000806428</rotorDragCoefficient>
        <rollingMomentCoefficient>1e-06</rollingMomentCoefficient>
        <motorSpeedPubTopic>prop_speed/2</motorSpeedPubTopic>
        <rotorVelocitySlowdownSim>10</rotorVelocitySlowdownSim>
      </plugin>
    
      <include>
        <uri>model://tsduav_t4_prop</uri>
        <name>tsduav_t4_prop_3</name>
        <pose>-0.53541 -1.00941 -0.0975 0 0 0</pose>
      </include>
      <joint name="tsduav_t4_prop_3_joint" type="revolute">
        <parent>tsduav_t4_base::base</parent>
        <child>tsduav_t4_prop_3::prop </child>
        <axis>
          <xyz>0 0 1</xyz>
          <limit>
            <lower>-1e+16</lower>
            <upper>1e+16</upper>
          </limit>
          <dynamics>
            <damping>0.00001</damping>
          </dynamics>
          <use_parent_model_frame>1</use_parent_model_frame>
        </axis>
      </joint>
      <plugin name="tsduav_t4_prop_3_plugin" filename='librotors_gazebo_motor_model.so'>
        <robotNamespace></robotNamespace>
        <jointName>tsduav_t4_prop_3_joint </jointName>
        <linkName>tsduav_t4_prop_3::prop</linkName>
        <turningDirection>ccw</turningDirection>
        <timeConstantUp>0.0125</timeConstantUp>
        <timeConstantDown>0.025</timeConstantDown>
        <maxRotVelocity>1000</maxRotVelocity>
        <motorConstant>8.599e-05</motorConstant>
        <momentConstant>0.25</momentConstant>
        <commandSubTopic>/gazebo/command/prop_speed</commandSubTopic>
        <motorNumber>3</motorNumber>
        <rotorDragCoefficient>0.000806428</rotorDragCoefficient>
        <rollingMomentCoefficient>1e-06</rollingMomentCoefficient>
        <motorSpeedPubTopic>prop_speed/3</motorSpeedPubTopic>
        <rotorVelocitySlowdownSim>10</rotorVelocitySlowdownSim>
      </plugin>
    
      <include>
        <uri>model://tsduav_t4_prop</uri>
        <name>tsduav_t4_prop_4</name>
        <pose>-0.53541 1.00941 0.0775 0 0 0</pose>
      </include>
      <joint name="tsduav_t4_prop_4_joint" type="revolute">
        <parent>tsduav_t4_base::base</parent>
        <child>tsduav_t4_prop_4::prop </child>
        <axis>
          <xyz>0 0 1</xyz>
          <limit>
            <lower>-1e+16</lower>
            <upper>1e+16</upper>
          </limit>
          <dynamics>
            <damping>0.00001</damping>
          </dynamics>
          <use_parent_model_frame>1</use_parent_model_frame>
        </axis>
      </joint>
      <plugin name="tsduav_t4_prop_4_plugin" filename='librotors_gazebo_motor_model.so'>
        <robotNamespace></robotNamespace>
        <jointName>tsduav_t4_prop_4_joint </jointName>
        <linkName>tsduav_t4_prop_4::prop</linkName>
        <turningDirection>ccw</turningDirection>
        <timeConstantUp>0.0125</timeConstantUp>
        <timeConstantDown>0.025</timeConstantDown>
        <maxRotVelocity>1000</maxRotVelocity>
        <motorConstant>8.599e-05</motorConstant>
        <momentConstant>0.25</momentConstant>
        <commandSubTopic>/gazebo/command/prop_speed</commandSubTopic>
        <motorNumber>4</motorNumber>
        <rotorDragCoefficient>0.000806428</rotorDragCoefficient>
        <rollingMomentCoefficient>1e-06</rollingMomentCoefficient>
        <motorSpeedPubTopic>prop_speed/4</motorSpeedPubTopic>
        <rotorVelocitySlowdownSim>10</rotorVelocitySlowdownSim>
      </plugin>
    
      <include>
        <uri>model://tsduav_t4_prop</uri>
        <name>tsduav_t4_prop_5</name>
        <pose>-0.53541 1.00941 -0.0975 0 0 0</pose>
      </include>
      <joint name="tsduav_t4_prop_5_joint" type="revolute">
        <parent>tsduav_t4_base::base</parent>
        <child>tsduav_t4_prop_5::prop </child>
        <axis>
          <xyz>0 0 1</xyz>
          <limit>
            <lower>-1e+16</lower>
            <upper>1e+16</upper>
          </limit>
          <dynamics>
            <damping>0.00001</damping>
          </dynamics>
          <use_parent_model_frame>1</use_parent_model_frame>
        </axis>
      </joint>
      <plugin name="tsduav_t4_prop_5_plugin" filename='librotors_gazebo_motor_model.so'>
        <robotNamespace></robotNamespace>
        <jointName>tsduav_t4_prop_5_joint </jointName>
        <linkName>tsduav_t4_prop_5::prop</linkName>
        <turningDirection>cw</turningDirection>
        <timeConstantUp>0.0125</timeConstantUp>
        <timeConstantDown>0.025</timeConstantDown>
        <maxRotVelocity>1000</maxRotVelocity>
        <motorConstant>8.599e-05</motorConstant>
        <momentConstant>0.25</momentConstant>
        <commandSubTopic>/gazebo/command/prop_speed</commandSubTopic>
        <motorNumber>5</motorNumber>
        <rotorDragCoefficient>0.000806428</rotorDragCoefficient>
        <rollingMomentCoefficient>1e-06</rollingMomentCoefficient>
        <motorSpeedPubTopic>prop_speed/5</motorSpeedPubTopic>
        <rotorVelocitySlowdownSim>10</rotorVelocitySlowdownSim>
      </plugin>
    
      <include>
        <uri>model://tsduav_t4_prop</uri>
        <name>tsduav_t4_prop_6</name>
        <pose>0.53541 1.00941 0.0775 0 0 0</pose>
      </include>
      <joint name="tsduav_t4_prop_6_joint" type="revolute">
        <parent>tsduav_t4_base::base</parent>
        <child>tsduav_t4_prop_6::prop </child>
        <axis>
          <xyz>0 0 1</xyz>
          <limit>
            <lower>-1e+16</lower>
            <upper>1e+16</upper>
          </limit>
          <dynamics>
            <damping>0.00001</damping>
          </dynamics>
          <use_parent_model_frame>1</use_parent_model_frame>
        </axis>
      </joint>
      <plugin name="tsduav_t4_prop_6_plugin" filename='librotors_gazebo_motor_model.so'>
        <robotNamespace></robotNamespace>
        <jointName>tsduav_t4_prop_6_joint </jointName>
        <linkName>tsduav_t4_prop_6::prop</linkName>
        <turningDirection>cw</turningDirection>
        <timeConstantUp>0.0125</timeConstantUp>
        <timeConstantDown>0.025</timeConstantDown>
        <maxRotVelocity>1000</maxRotVelocity>
        <motorConstant>8.599e-05</motorConstant>
        <momentConstant>0.25</momentConstant>
        <commandSubTopic>/gazebo/command/prop_speed</commandSubTopic>
        <motorNumber>6</motorNumber>
        <rotorDragCoefficient>0.000806428</rotorDragCoefficient>
        <rollingMomentCoefficient>1e-06</rollingMomentCoefficient>
        <motorSpeedPubTopic>prop_speed/6</motorSpeedPubTopic>
        <rotorVelocitySlowdownSim>10</rotorVelocitySlowdownSim>
      </plugin>
    
      <include>
        <uri>model://tsduav_t4_prop</uri>
        <name>tsduav_t4_prop_7</name>
        <pose>0.53541 1.00941 -0.0975 0 0 0</pose>
      </include>
      <joint name="tsduav_t4_prop_7_joint" type="revolute">
        <parent>tsduav_t4_base::base</parent>
        <child>tsduav_t4_prop_7::prop </child>
        <axis>
          <xyz>0 0 1</xyz>
          <limit>
            <lower>-1e+16</lower>
            <upper>1e+16</upper>
          </limit>
          <dynamics>
            <damping>0.00001</damping>
          </dynamics>
          <use_parent_model_frame>1</use_parent_model_frame>
        </axis>
      </joint>
      <plugin name="tsduav_t4_prop_7_plugin" filename='librotors_gazebo_motor_model.so'>
        <robotNamespace></robotNamespace>
        <jointName>tsduav_t4_prop_7_joint </jointName>
        <linkName>tsduav_t4_prop_7::prop</linkName>
        <turningDirection>ccw</turningDirection>
        <timeConstantUp>0.0125</timeConstantUp>
        <timeConstantDown>0.025</timeConstantDown>
        <maxRotVelocity>1000</maxRotVelocity>
        <motorConstant>8.599e-05</motorConstant>
        <momentConstant>0.25</momentConstant>
        <commandSubTopic>/gazebo/command/prop_speed</commandSubTopic>
        <motorNumber>7</motorNumber>
        <rotorDragCoefficient>0.000806428</rotorDragCoefficient>
        <rollingMomentCoefficient>1e-06</rollingMomentCoefficient>
        <motorSpeedPubTopic>prop_speed/7</motorSpeedPubTopic>
        <rotorVelocitySlowdownSim>10</rotorVelocitySlowdownSim>
      </plugin>
    
    <include>
      <uri>model://tsduav_t4_link</uri>
      <name>tsduav_t4_link</name>
      <pose>1.034 0 -0.226 0 -1.5707963267948966 0</pose>
    </include>
    <joint name='link_base_joint' type='revolute'>
      <parent>tsduav_t4_link::link_base</parent>
      <child>tsduav_t4_base::base</child>
      <pose>0 0 -0.226 0 -1.5707963267948966 0</pose>
      <axis>
          <xyz>0 -1 0</xyz>
          <limit>
            <lower>-3.141592653589793</lower>
            <upper>1.5707963267948966</upper>
          </limit>
          <dynamics>
            <damping>0.001</damping>
          </dynamics>
          <use_parent_model_frame>1</use_parent_model_frame>
        </axis>
    </joint>
    
    <include>
      <uri>model://tsduav_t4_saw</uri>
      <name>tsduav_t4_saw</name>
      <pose>1.6 0 -0.226 0 0 0</pose>
    </include>
    <joint name='tsduav_t4_saw_1_joint' type='fixed'>
      <child>tsduav_t4_saw::saw</child>
      <parent>tsduav_t4_link::link_base</parent>
      <use_parent_model_frame>1</use_parent_model_frame>
    </joint>

    <plugin name="ArduRotorQuadOctPlugin" filename="libArduRotorQuadOctPlugin.so">
      <fdm_addr>127.0.0.1</fdm_addr>
      <fdm_port_in>9002</fdm_port_in>
      <fdm_port_out>9003</fdm_port_out>
      <modelXYZToAirplaneXForwardZDown>0 0 0 3.141593 0 0</modelXYZToAirplaneXForwardZDown>
      <gazeboXYZToNED>0 0 0 3.141593 0 0</gazeboXYZToNED>
      <motor_num>8</motor_num>
      <motor_pub>/gazebo/command/prop_speed</motor_pub>
      <imuName>tsduav_t4::tsduav_t4_base::imu_link::imu_sensor</imuName>
      <connectionTimeoutMaxCount>5</connectionTimeoutMaxCount>
    </plugin>
  </model>
</sdf>
