<?xml version="1.0" ?>
  <%

  # ----------------------------------------------------------------
  platform_base_dx = 0
  platform_base_dy = 0
  platform_base_dz = 0.0

  platform_base_mass = 2.36

  platform_base_ixx  = 0.1
  platform_base_iyy  = 0.2
  platform_base_izz  = 0.1

  # ----------------------------------------------------------------
  platform_tilt_mass = 0.20
  platform_tilt_ixx = 0.001
  platform_tilt_iyy = 0.001
  platform_tilt_izz = 0.001

  platform_tilt_0_dx = 0.251
  platform_tilt_0_dy = -0.321
  platform_tilt_0_dz = platform_base_dz + 0.0
  platform_tilt_0_rad = 0.0

  platform_tilt_1_dx = -0.251
  platform_tilt_1_dy = -0.321
  platform_tilt_1_dz = platform_base_dz + 0.0
  platform_tilt_1_rad = 0.0

  platform_tilt_2_dx = -0.251
  platform_tilt_2_dy = 0.321
  platform_tilt_2_dz = platform_base_dz + 0.0
  platform_tilt_2_rad = Math::PI

  platform_tilt_3_dx = 0.251
  platform_tilt_3_dy = 0.321
  platform_tilt_3_dz = platform_base_dz + 0.0
  platform_tilt_3_rad = Math::PI

  platform_tilt_pos={
    "tilt_0" => {:x0 => platform_tilt_0_dx, :y0 => platform_tilt_0_dy, :z0 => platform_tilt_0_dz, :rad => platform_tilt_0_rad},
    "tilt_1" => {:x0 => platform_tilt_1_dx, :y0 => platform_tilt_1_dy, :z0 => platform_tilt_1_dz, :rad => platform_tilt_1_rad},
    "tilt_2" => {:x0 => platform_tilt_2_dx, :y0 => platform_tilt_2_dy, :z0 => platform_tilt_2_dz, :rad => platform_tilt_2_rad},
    "tilt_3" => {:x0 => platform_tilt_3_dx, :y0 => platform_tilt_3_dy, :z0 => platform_tilt_3_dz, :rad => platform_tilt_3_rad},
  }

  # ----------------------------------------------------------------
  prop_mass = 0.04
  prop_ixx = 0.001
  prop_iyy = 0.001
  prop_izz = 0.001

  prop_0_dx = 0.251
  prop_0_dy = -0.33025
  prop_0_dz = platform_base_dz + 0.070146
  
  prop_1_dx = -0.251
  prop_1_dy = -0.33025
  prop_1_dz = platform_base_dz + 0.070146

  prop_2_dx = -0.251
  prop_2_dy = 0.33025
  prop_2_dz = platform_base_dz + 0.070146

  prop_3_dx = 0.251
  prop_3_dy = 0.33025
  prop_3_dz = platform_base_dz + 0.070146

  prop_pos={
    "prop_0" => {:x0 => prop_0_dx, :y0 => prop_0_dy, :z0 => prop_0_dz, :stl => "model://arduwoodpecker_platform/meshes/prop_ccw.STL", :parent => "tilt_0", :dir => "1"},
    "prop_1" => {:x0 => prop_1_dx, :y0 => prop_1_dy, :z0 => prop_1_dz, :stl => "model://arduwoodpecker_platform/meshes/prop_cw.STL", :parent => "tilt_1", :dir => "1"},
    "prop_2" => {:x0 => prop_2_dx, :y0 => prop_2_dy, :z0 => prop_2_dz, :stl => "model://arduwoodpecker_platform/meshes/prop_ccw.STL", :parent => "tilt_2", :dir => "1"},
    "prop_3" => {:x0 => prop_3_dx, :y0 => prop_3_dy, :z0 => prop_3_dz, :stl => "model://arduwoodpecker_platform/meshes/prop_cw.STL", :parent => "tilt_3", :dir => "1"},
  }

%>
  <sdf version="1.5">
    <model name="arduwoodpecker_platform">
      <%# ----------------------------------------------------------- %>
      <link name="platform_base">
      <pose>0 0 <%= platform_base_dz %>  0 0 0</pose>
      <inertial>
        <pose>0 0 0 0 0 0</pose>
        <mass><%= platform_base_mass %></mass>
        <inertia>
          <ixx><%= platform_base_ixx %></ixx>
          <iyy><%= platform_base_iyy %></iyy>
          <izz><%= platform_base_izz %></izz>
          <ixy>0</ixy>
          <ixz>0</ixz>
          <iyz>0</iyz>
        </inertia>
      </inertial>
      <collision name="platform_base_collision">
        <geometry>
          <box>
            <size>0.558 0.148 0.031</size>
          </box>
        </geometry>
        <surface>
          <contact>
            <ode>
              <max_vel>100.0</max_vel>
              <min_depth>0.001</min_depth>
            </ode>
          </contact>
          <friction>
            <ode>
              <mu>100000.0</mu>
              <mu2>100000.0</mu2>
            </ode>
          </friction>
        </surface>
      </collision>
      <visual name="platform_base_visual">
        <geometry>
          <mesh>
            <uri>model://arduwoodpecker_platform/meshes/platform_base.STL</uri>
          </mesh>
        </geometry>
        <material>
          <script>
            <name>Gazebo/Grey</name>
          </script>
        </material>
      </visual>
    </link>
    <%# ----------------------------------------------------------- %>
    <%
      platform_tilt_pos.keys.each do |k|
        x0 = platform_tilt_pos[k][:x0]
        y0 = platform_tilt_pos[k][:y0]
        z0 = platform_tilt_pos[k][:z0]
        rad = platform_tilt_pos[k][:rad]
    %>
    <%= "<link name=" + '"' + k + '"' + '>' %>
    <pose><%= x0 %> <%= y0 %> <%= z0 %>  0 0 <%= rad %></pose>
    <inertial>
      <pose>0 0 0 0 0 0</pose>
      <mass><%= platform_tilt_mass %></mass>
      <inertia>
        <ixx><%= platform_tilt_ixx %></ixx>
        <iyy><%= platform_tilt_iyy %></iyy>
        <izz><%= platform_tilt_izz %></izz>
        <ixy>0</ixy>
        <ixz>0</ixz>
        <iyz>0</iyz>
      </inertia>
    </inertial>
    <%= "<collision name=" + '"' + k + "_collision" + '"' + '>' %>
    <geometry>
      <mesh>
        <uri>model://arduwoodpecker_platform/meshes/platform_tilt.STL</uri>
      </mesh>
    </geometry>
  </collision>
  <%= "<visual name=" + '"' + k + "_visual" + '"' + '>' %>
  <geometry>
    <mesh>
      <uri>model://arduwoodpecker_platform/meshes/platform_tilt.STL</uri>
    </mesh>
  </geometry>
</visual>
</link>
<%= "<joint name=" + '"' + k + '_joint" type="fixed">' %>
<parent>platform_base</parent>
<%= "<child>" + k + "</child>" %>
<pose>-0.0 0 0.0 0 0 0</pose>
<axis>
  <xyz>0 1 0</xyz>
  <limit>
    <lower><%= -Math::PI %></lower>
    <upper><%= Math::PI %></upper>
  </limit>
</axis>
</joint>
<% end %>
<%# ----------------------------------------------------------- %>
<%
      prop_pos.keys.each do |k|
        x0 = prop_pos[k][:x0]
        y0 = prop_pos[k][:y0]
        z0 = prop_pos[k][:z0]
        stl = prop_pos[k][:stl]
        parent = prop_pos[k][:parent]
        dir = prop_pos[k][:dir]
    %>
<%= "<link name=" + '"' + k + '"' + '>' %>
<pose><%= x0 %> <%= y0 %> <%= z0 %>  0 0 0</pose>
<inertial>
  <pose>0 0 0 0 0 0</pose>
  <mass><%= prop_mass %></mass>
  <inertia>
    <ixx><%= prop_ixx %></ixx>
    <iyy><%= prop_iyy %></iyy>
    <izz><%= prop_izz %></izz>
    <ixy>0</ixy>
    <ixz>0</ixz>
    <iyz>0</iyz>
  </inertia>
</inertial>
<%= "<collision name=" + '"' + k + "_collision" + '"' + '>' %>
<geometry>
  <mesh>
    <uri><%= stl%></uri>
  </mesh>
</geometry>
</collision>
<%= "<visual name=" + '"' + k + "_visual" + '"' + '>' %>
<geometry>
  <mesh>
    <uri><%= stl%></uri>
  </mesh>
</geometry>
</visual>
</link>
<%= "<joint name=" + '"' + k + '_joint" type="revolute">' %>
<parent><%= parent%></parent>
<%= "<child>" + k + "</child>" %>
<pose>-0.0 0 0.0 0 0 0</pose>
<axis>
  <xyz>0 0 <%= dir %></xyz>
  <limit>
    <lower>-1e+16</lower>
    <upper>1e+16</upper>
  </limit>
  <dynamics>
    <damping>0.004</damping>
  </dynamics>
  <use_parent_model_frame>1</use_parent_model_frame>
</axis>
<physics>
  <ode>
    <implicit_spring_damper>1</implicit_spring_damper>
  </ode>
</physics>
</joint>
<% end %>
</model>
</sdf>
