<?xml version="1.0" ?>
  
  <sdf version="1.5">
    <model name="tsduav_quad">
      
      <include>
        <uri>model://tsduav_quad_base</uri>
        <name>tsduav_quad_base</name>
        <pose>0 0 0.0 0 0 0</pose>
      </include>
      <include>
        <uri>model://tsduav_quad_prop</uri>
        <name>tsduav_quad_prop_0</name>
        <pose>0.389 -0.389 0.0465 0 0 0</pose>
      </include>
      <include>
        <uri>model://tsduav_quad_prop</uri>
        <name>tsduav_quad_prop_1</name>
        <pose>-0.389 -0.389 0.0465 0 0 0</pose>
      </include>
      <include>
        <uri>model://tsduav_quad_prop</uri>
        <name>tsduav_quad_prop_2</name>
        <pose>-0.389 0.389 0.0465 0 0 3.141592653589793</pose>
      </include>
      <include>
        <uri>model://tsduav_quad_prop</uri>
        <name>tsduav_quad_prop_3</name>
        <pose>0.389 0.389 0.0465 0 0 3.141592653589793</pose>
      </include>
      
      <joint name="tsduav_quad_prop_0_joint" type="revolute">
        <parent>tsduav_quad_base::platform_base</parent>
        <child>tsduav_quad_prop_0::prop </child>
        <axis>
          <xyz>0 0 1</xyz>
          <limit>
            <lower>-1e+16</lower>
            <upper>1e+16</upper>
          </limit>
          <dynamics>
            <damping>0.00001</damping>
          </dynamics>
          <use_parent_model_frame>1</use_parent_model_frame>
        </axis>
      </joint>
      
      <plugin name="tsduav_quad_prop_0_plugin" filename='librotors_gazebo_motor_model.so'>
        <robotNamespace></robotNamespace>
        <jointName>tsduav_quad_prop_0_joint </jointName>
        <linkName>tsduav_quad_prop_0::prop</linkName>
        <turningDirection>ccw</turningDirection>
        <timeConstantUp>0.0125</timeConstantUp>
        <timeConstantDown>0.025</timeConstantDown>
        <maxRotVelocity>1000</maxRotVelocity>
        <motorConstant>8.599e-05</motorConstant>
        <momentConstant>0.25</momentConstant>
        <commandSubTopic>/gazebo/command/prop_speed</commandSubTopic>
        <motorNumber>0</motorNumber>
        <rotorDragCoefficient>0.000806428</rotorDragCoefficient>
        <rollingMomentCoefficient>1e-06</rollingMomentCoefficient>
        <motorSpeedPubTopic>prop_speed/0</motorSpeedPubTopic>
        <rotorVelocitySlowdownSim>10</rotorVelocitySlowdownSim>
      </plugin>
    
      <joint name="tsduav_quad_prop_1_joint" type="revolute">
        <parent>tsduav_quad_base::platform_base</parent>
        <child>tsduav_quad_prop_1::prop </child>
        <axis>
          <xyz>0 0 1</xyz>
          <limit>
            <lower>-1e+16</lower>
            <upper>1e+16</upper>
          </limit>
          <dynamics>
            <damping>0.00001</damping>
          </dynamics>
          <use_parent_model_frame>1</use_parent_model_frame>
        </axis>
      </joint>
      
      <plugin name="tsduav_quad_prop_1_plugin" filename='librotors_gazebo_motor_model.so'>
        <robotNamespace></robotNamespace>
        <jointName>tsduav_quad_prop_1_joint </jointName>
        <linkName>tsduav_quad_prop_1::prop</linkName>
        <turningDirection>cw</turningDirection>
        <timeConstantUp>0.0125</timeConstantUp>
        <timeConstantDown>0.025</timeConstantDown>
        <maxRotVelocity>1000</maxRotVelocity>
        <motorConstant>8.599e-05</motorConstant>
        <momentConstant>0.25</momentConstant>
        <commandSubTopic>/gazebo/command/prop_speed</commandSubTopic>
        <motorNumber>1</motorNumber>
        <rotorDragCoefficient>0.000806428</rotorDragCoefficient>
        <rollingMomentCoefficient>1e-06</rollingMomentCoefficient>
        <motorSpeedPubTopic>prop_speed/1</motorSpeedPubTopic>
        <rotorVelocitySlowdownSim>10</rotorVelocitySlowdownSim>
      </plugin>
    
      <joint name="tsduav_quad_prop_2_joint" type="revolute">
        <parent>tsduav_quad_base::platform_base</parent>
        <child>tsduav_quad_prop_2::prop </child>
        <axis>
          <xyz>0 0 1</xyz>
          <limit>
            <lower>-1e+16</lower>
            <upper>1e+16</upper>
          </limit>
          <dynamics>
            <damping>0.00001</damping>
          </dynamics>
          <use_parent_model_frame>1</use_parent_model_frame>
        </axis>
      </joint>
      
      <plugin name="tsduav_quad_prop_2_plugin" filename='librotors_gazebo_motor_model.so'>
        <robotNamespace></robotNamespace>
        <jointName>tsduav_quad_prop_2_joint </jointName>
        <linkName>tsduav_quad_prop_2::prop</linkName>
        <turningDirection>ccw</turningDirection>
        <timeConstantUp>0.0125</timeConstantUp>
        <timeConstantDown>0.025</timeConstantDown>
        <maxRotVelocity>1000</maxRotVelocity>
        <motorConstant>8.599e-05</motorConstant>
        <momentConstant>0.25</momentConstant>
        <commandSubTopic>/gazebo/command/prop_speed</commandSubTopic>
        <motorNumber>2</motorNumber>
        <rotorDragCoefficient>0.000806428</rotorDragCoefficient>
        <rollingMomentCoefficient>1e-06</rollingMomentCoefficient>
        <motorSpeedPubTopic>prop_speed/2</motorSpeedPubTopic>
        <rotorVelocitySlowdownSim>10</rotorVelocitySlowdownSim>
      </plugin>
    
      <joint name="tsduav_quad_prop_3_joint" type="revolute">
        <parent>tsduav_quad_base::platform_base</parent>
        <child>tsduav_quad_prop_3::prop </child>
        <axis>
          <xyz>0 0 1</xyz>
          <limit>
            <lower>-1e+16</lower>
            <upper>1e+16</upper>
          </limit>
          <dynamics>
            <damping>0.00001</damping>
          </dynamics>
          <use_parent_model_frame>1</use_parent_model_frame>
        </axis>
      </joint>
      
      <plugin name="tsduav_quad_prop_3_plugin" filename='librotors_gazebo_motor_model.so'>
        <robotNamespace></robotNamespace>
        <jointName>tsduav_quad_prop_3_joint </jointName>
        <linkName>tsduav_quad_prop_3::prop</linkName>
        <turningDirection>cw</turningDirection>
        <timeConstantUp>0.0125</timeConstantUp>
        <timeConstantDown>0.025</timeConstantDown>
        <maxRotVelocity>1000</maxRotVelocity>
        <motorConstant>8.599e-05</motorConstant>
        <momentConstant>0.25</momentConstant>
        <commandSubTopic>/gazebo/command/prop_speed</commandSubTopic>
        <motorNumber>3</motorNumber>
        <rotorDragCoefficient>0.000806428</rotorDragCoefficient>
        <rollingMomentCoefficient>1e-06</rollingMomentCoefficient>
        <motorSpeedPubTopic>prop_speed/3</motorSpeedPubTopic>
        <rotorVelocitySlowdownSim>10</rotorVelocitySlowdownSim>
      </plugin>
    
    <plugin name="ArduRotorNormPlugin" filename="libArduRotorNormPlugin.so">
      <fdm_addr>127.0.0.1</fdm_addr>
      <fdm_port_in>9002</fdm_port_in>
      <fdm_port_out>9003</fdm_port_out>
      <modelXYZToAirplaneXForwardZDown>0 0 0 3.141593 0 0</modelXYZToAirplaneXForwardZDown>
      <gazeboXYZToNED>0 0 0 3.141593 0 0</gazeboXYZToNED>
      <motor_num>4</motor_num>
      <servo_num>0</servo_num>
      <motor_pub>/gazebo/command/prop_speed</motor_pub>
      <imuName>tsduav_quad_base::imu_link::imu_sensor</imuName>
      <connectionTimeoutMaxCount>5</connectionTimeoutMaxCount>
    </plugin>
  </model>
  
</sdf>
