<?xml version="1.0" ?>
  
  <sdf version="1.5">
    <model name="iwp_claw">
      <link name="claw_base">
      <pose>0 0 0.0  0 0 0</pose>
      <inertial>
        <pose>0 0 0 0 0 0</pose>
        <mass>0.5</mass>
        <inertia>
          <ixx>0.02</ixx>
          <iyy>0.04</iyy>
          <izz>0.01</izz>
          <ixy>0</ixy>
          <ixz>0</ixz>
          <iyz>0</iyz>
        </inertia>
      </inertial>
      <collision name="claw_base_collision">
        <geometry>
          <box>
            <size>0.051 0.130 0.166</size>
          </box>
        </geometry>
        <surface>
          <contact>
            <ode>
              <max_vel>100.0</max_vel>
              <min_depth>0.001</min_depth>
            </ode>
          </contact>
          <friction>
            <ode>
              <mu>100000.0</mu>
              <mu2>100000.0</mu2>
            </ode>
          </friction>
        </surface>
      </collision>
      <visual name="claw_base_visual">
        <geometry>
          <mesh>
            <uri>model://iwp_claw/meshes/claw_base.STL</uri>
          </mesh>
        </geometry>
        <material>
          <script>
            <name>Gazebo/Grey</name>
          </script>
        </material>
      </visual>
    </link>
    
    
    <include>
      <uri>model://iwp_claw_pole</uri>
      <name>left_pole_0</name>
      <pose>-0.0 0.080999 -0.124216 0.6113888369736137 0 0</pose>
    </include>
    <joint name="left_pole_0_joint" type="revolute">
      <parent>claw_base</parent>
      <child>left_pole_0::base_link</child>
      <pose>0 0 0.054 0 0 0</pose>
      <axis>
        <xyz>1 0 0</xyz>
        <limit>
          <lower>-1.5707963267948966</lower>
          <upper>1.5707963267948966</upper>
        </limit>
      </axis>
      <dynamics>
        <damping>0.004</damping>
      </dynamics>
      <use_parent_model_frame>1</use_parent_model_frame>
      <physics>
        <ode>
          <implicit_spring_damper>1</implicit_spring_damper>
        </ode>
      </physics>
    </joint>
  
    <include>
      <uri>model://iwp_claw_pole</uri>
      <name>left_pole_1</name>
      <pose>-0.0 0.055999 -0.124216 0.6113888369736137 0 0</pose>
    </include>
    <joint name="left_pole_1_joint" type="revolute">
      <parent>claw_base</parent>
      <child>left_pole_1::base_link</child>
      <pose>0 0 0.054 0 0 0</pose>
      <axis>
        <xyz>1 0 0</xyz>
        <limit>
          <lower>-1.5707963267948966</lower>
          <upper>1.5707963267948966</upper>
        </limit>
      </axis>
      <dynamics>
        <damping>0.004</damping>
      </dynamics>
      <use_parent_model_frame>1</use_parent_model_frame>
      <physics>
        <ode>
          <implicit_spring_damper>1</implicit_spring_damper>
        </ode>
      </physics>
    </joint>
  
    <include>
      <uri>model://iwp_claw_pole</uri>
      <name>right_pole_0</name>
      <pose>0.0 -0.080999 -0.124216 -0.6113888369736137 0 0</pose>
    </include>
    <joint name="right_pole_0_joint" type="revolute">
      <parent>claw_base</parent>
      <child>right_pole_0::base_link</child>
      <pose>0 0 0.054 0 0 0</pose>
      <axis>
        <xyz>1 0 0</xyz>
        <limit>
          <lower>-1.5707963267948966</lower>
          <upper>1.5707963267948966</upper>
        </limit>
      </axis>
      <dynamics>
        <damping>0.004</damping>
      </dynamics>
      <use_parent_model_frame>1</use_parent_model_frame>
      <physics>
        <ode>
          <implicit_spring_damper>1</implicit_spring_damper>
        </ode>
      </physics>
    </joint>
  
    <include>
      <uri>model://iwp_claw_pole</uri>
      <name>right_pole_1</name>
      <pose>0.0 -0.055999 -0.124216 -0.6113888369736137 0 0</pose>
    </include>
    <joint name="right_pole_1_joint" type="revolute">
      <parent>claw_base</parent>
      <child>right_pole_1::base_link</child>
      <pose>0 0 0.054 0 0 0</pose>
      <axis>
        <xyz>1 0 0</xyz>
        <limit>
          <lower>-1.5707963267948966</lower>
          <upper>1.5707963267948966</upper>
        </limit>
      </axis>
      <dynamics>
        <damping>0.004</damping>
      </dynamics>
      <use_parent_model_frame>1</use_parent_model_frame>
      <physics>
        <ode>
          <implicit_spring_damper>1</implicit_spring_damper>
        </ode>
      </physics>
    </joint>
  
  
  <include>
    <uri>model://iwp_claw_hand</uri>
    <name>hand_left_0</name>
    <pose>-0.0 0.101185 -0.207357 0 0 0 </pose>
  </include>
  <joint name="hand_left_0_joint" type="revolute">
    <parent>left_pole_0::base_link</parent>
    <child>hand_left_0::base_link</child>
    <pose>0 0.010813 0.038925 0 0 0</pose>
    <axis>
      <xyz>1 0 0</xyz>
      <limit>
        <lower>-1.5707963267948966</lower>
        <upper>1.5707963267948966</upper>
      </limit>
    </axis>
    <dynamics>
      <damping>0.004</damping>
    </dynamics>
    <use_parent_model_frame>1</use_parent_model_frame>
    <physics>
      <ode>
        <implicit_spring_damper>1</implicit_spring_damper>
      </ode>
    </physics>
  </joint>
  <joint name="hand_left_0_2_joint" type="revolute">
    <parent>left_pole_1::base_link</parent>
    <child>hand_left_0::base_link</child>
    <pose>0 -0.014187 0.038925 0 0 0</pose>
    <axis>
      <xyz>1 0 0</xyz>
      <limit>
        <lower>-1.5707963267948966</lower>
        <upper>1.5707963267948966</upper>
      </limit>
    </axis>
    <dynamics>
      <damping>0.004</damping>
    </dynamics>
    <use_parent_model_frame>1</use_parent_model_frame>
    <physics>
      <ode>
        <implicit_spring_damper>1</implicit_spring_damper>
      </ode>
    </physics>
  </joint>

  <include>
    <uri>model://iwp_claw_hand</uri>
    <name>hand_right_0</name>
    <pose>0.0 -0.101185 -0.207357 0 0 3.141592653589793 </pose>
  </include>
  <joint name="hand_right_0_joint" type="revolute">
    <parent>right_pole_0::base_link</parent>
    <child>hand_right_0::base_link</child>
    <pose>0 0.010813 0.038925 0 0 0</pose>
    <axis>
      <xyz>1 0 0</xyz>
      <limit>
        <lower>-1.5707963267948966</lower>
        <upper>1.5707963267948966</upper>
      </limit>
    </axis>
    <dynamics>
      <damping>0.004</damping>
    </dynamics>
    <use_parent_model_frame>1</use_parent_model_frame>
    <physics>
      <ode>
        <implicit_spring_damper>1</implicit_spring_damper>
      </ode>
    </physics>
  </joint>
  <joint name="hand_right_0_2_joint" type="revolute">
    <parent>right_pole_1::base_link</parent>
    <child>hand_right_0::base_link</child>
    <pose>0 -0.014187 0.038925 0 0 0</pose>
    <axis>
      <xyz>1 0 0</xyz>
      <limit>
        <lower>-1.5707963267948966</lower>
        <upper>1.5707963267948966</upper>
      </limit>
    </axis>
    <dynamics>
      <damping>0.004</damping>
    </dynamics>
    <use_parent_model_frame>1</use_parent_model_frame>
    <physics>
      <ode>
        <implicit_spring_damper>1</implicit_spring_damper>
      </ode>
    </physics>
  </joint>



<include>
  <uri>model://iwp_claw_tie</uri>
  <name>tie_left_0</name>
  <pose>-0.0 0.034 -0.124108 1.5707963267948966 0 0</pose>
</include>
<joint name="tie_left_0_joint" type="revolute">
  <parent>left_pole_1::base_link</parent>
  <child>tie_left_0::base_link</child>
  <pose>0 0 -0.022 0 0 0</pose>
  <axis>
    <xyz>1 0 0</xyz>
    <limit>
      <lower>-1.5707963267948966</lower>
      <upper>1.5707963267948966</upper>
    </limit>
  </axis>
  <dynamics>
    <damping>0.004</damping>
  </dynamics>
  <use_parent_model_frame>1</use_parent_model_frame>
  <physics>
    <ode>
      <implicit_spring_damper>1</implicit_spring_damper>
    </ode>
  </physics>
</joint>
<joint name="tie_left_0_2_joint" type="revolute">
  <parent>claw_flange</parent>
  <child>tie_left_0::base_link</child>
  <pose>0 0 0.022 0 0 0</pose>
  <axis>
    <xyz>1 0 0</xyz>
    <limit>
      <lower>-1.5707963267948966</lower>
      <upper>1.5707963267948966</upper>
    </limit>
  </axis>
  <dynamics>
    <damping>0.004</damping>
  </dynamics>
  <use_parent_model_frame>1</use_parent_model_frame>
  <physics>
    <ode>
      <implicit_spring_damper>1</implicit_spring_damper>
    </ode>
  </physics>
</joint>

<include>
  <uri>model://iwp_claw_tie</uri>
  <name>tie_right_0</name>
  <pose>0.0 -0.034 -0.124108 -1.5707963267948966 0 0</pose>
</include>
<joint name="tie_right_0_joint" type="revolute">
  <parent>right_pole_1::base_link</parent>
  <child>tie_right_0::base_link</child>
  <pose>0 0 -0.022 0 0 0</pose>
  <axis>
    <xyz>1 0 0</xyz>
    <limit>
      <lower>-1.5707963267948966</lower>
      <upper>1.5707963267948966</upper>
    </limit>
  </axis>
  <dynamics>
    <damping>0.004</damping>
  </dynamics>
  <use_parent_model_frame>1</use_parent_model_frame>
  <physics>
    <ode>
      <implicit_spring_damper>1</implicit_spring_damper>
    </ode>
  </physics>
</joint>
<joint name="tie_right_0_2_joint" type="revolute">
  <parent>claw_flange</parent>
  <child>tie_right_0::base_link</child>
  <pose>0 0 0.022 0 0 0</pose>
  <axis>
    <xyz>1 0 0</xyz>
    <limit>
      <lower>-1.5707963267948966</lower>
      <upper>1.5707963267948966</upper>
    </limit>
  </axis>
  <dynamics>
    <damping>0.004</damping>
  </dynamics>
  <use_parent_model_frame>1</use_parent_model_frame>
  <physics>
    <ode>
      <implicit_spring_damper>1</implicit_spring_damper>
    </ode>
  </physics>
</joint>


<link name="claw_flange">
<pose>0 0 -0.123 0 0 3.141592653589793</pose>
<inertial>
  <pose>0 0 0 0 0 0</pose>
  <mass>0.028</mass>
  <inertia>
    <ixx>0.02</ixx>
    <iyy>0.01</iyy>
    <izz>0.01</izz>
    <ixy>0</ixy>
    <ixz>0</ixz>
    <iyz>0</iyz>
  </inertia>
</inertial>
<collision name="claw_flange_collision">
  <geometry>
    <mesh>
      <uri>model://iwp_claw/meshes/claw_flange.STL</uri>
    </mesh>
  </geometry>
</collision>
<visual name="claw_flange_visual">
  <geometry>
    <mesh>
      <uri>model://iwp_claw/meshes/claw_flange.STL</uri>
    </mesh>
  </geometry>
</visual>
</link>
<joint name="claw_flange_joint" type="prismatic">
  
  <parent>claw_base</parent>
  <child>claw_flange</child>
  <pose>0 0 -0.0 0 0 0</pose>
  <axis>
    <xyz>0 0 1</xyz>
    <limit>
      <lower>0</lower>
      <upper>0.034</upper>
    </limit>
  </axis>
  <dynamics>
    <damping>0.004</damping>
  </dynamics>
  <use_parent_model_frame>1</use_parent_model_frame>
  <physics>
    <ode>
      <implicit_spring_damper>1</implicit_spring_damper>
    </ode>
  </physics>
</joint>
</model>
</sdf>
