<?xml version="1.0" ?>
  
  <sdf version="1.5">
    <model name="tsduav_t4_link">
      
      <link name="link_base">
      <pose>0 0 0 0 0 0</pose>
      <inertial>
        <pose>0 0 0 0 0 0</pose>
        <mass>0.2</mass>
        <inertia>
          <ixx>0.01</ixx>
          <iyy>0.01</iyy>
          <izz>0.01</izz>
          <ixy>0</ixy>
          <ixz>0</ixz>
          <iyz>0</iyz>
        </inertia>
      </inertial>
      <collision name="link_base_collision">
        <pose>0 0 0 0 0 0</pose>
        <geometry>
          <box>
            <size>0.1 0.655  0.255</size>
          </box>
        </geometry>
        <surface>
          <contact>
            <ode>
              <max_vel>100.0</max_vel>
              <min_depth>0.001</min_depth>
            </ode>
          </contact>
          <friction>
            <ode>
              <mu>100000.0</mu>
              <mu2>100000.0</mu2>
            </ode>
          </friction>
        </surface>
      </collision>
      <visual name="link_base_visual">
        <geometry>
          <mesh>
            <uri>model://tsduav_t4_link/meshes/link_base.STL</uri>
          </mesh>
        </geometry>
        <material>
          <script>
            <name>Gazebo/Yellow</name>
          </script>
        </material>
      </visual>
    </link>
    <link name="link_pipe_1">
    <pose>-0.0 0.243 -0.1995 0 -1.5707963267948966 0</pose>
    <inertial>
      <pose>0 0 0 0 0 0</pose>
      <mass>0.5</mass>
      <inertia>
        <ixx>0.02</ixx>
        <iyy>0.03</iyy>
        <izz>0.01</izz>
        <ixy>0</ixy>
        <ixz>0</ixz>
        <iyz>0</iyz>
      </inertia>
    </inertial>
    <collision name="link_pipe_1_collision">
      <pose>0 0 -0.65 0 0 0</pose>
      <geometry>
        <cylinder>
          <length>1.35</length>
          <radius>0.0275</radius>
        </cylinder>
      </geometry>
      <surface>
        <contact>
          <ode>
            <max_vel>100.0</max_vel>
            <min_depth>0.001</min_depth>
          </ode>
        </contact>
        <friction>
          <ode>
            <mu>100000.0</mu>
            <mu2>100000.0</mu2>
          </ode>
        </friction>
      </surface>
    </collision>
    <visual name="link_pipe_1_visual">
      <geometry>
        <mesh>
          <uri>model://tsduav_t4_link/meshes/link_pipe.STL</uri>
        </mesh>
      </geometry>
      <material>
        <script>
          <name>Gazebo/Green</name>
        </script>
      </material>
    </visual>
  </link>
  <joint name='link_pipe_1_joint' type="revolute">
    <parent>link_base</parent>
    <child>link_pipe_1</child>
    <axis>
      <xyz>0 1 0</xyz>
      <limit>
        <lower>-1.5707963267948966</lower>
        <upper>1.5707963267948966</upper>
      </limit>
      <dynamics>
        <damping>0.00001</damping>
      </dynamics>
      <use_parent_model_frame>1</use_parent_model_frame>
    </axis>
  </joint>
  
  <link name="link_pipe_2">
  <pose>-0.0 -0.243 -0.1995 0 -1.5707963267948966 0</pose>
  <inertial>
    <pose>0 0 0 0 0 0</pose>
    <mass>0.5</mass>
    <inertia>
      <ixx>0.02</ixx>
      <iyy>0.03</iyy>
      <izz>0.01</izz>
      <ixy>0</ixy>
      <ixz>0</ixz>
      <iyz>0</iyz>
    </inertia>
  </inertial>
  <collision name="link_pipe_2_collision">
    <pose>0 0 -0.65 0 0 0</pose>
    <geometry>
      <cylinder>
        <length>1.35</length>
        <radius>0.0275</radius>
      </cylinder>
    </geometry>
    <surface>
      <contact>
        <ode>
          <max_vel>100.0</max_vel>
          <min_depth>0.001</min_depth>
        </ode>
      </contact>
      <friction>
        <ode>
          <mu>100000.0</mu>
          <mu2>100000.0</mu2>
        </ode>
      </friction>
    </surface>
  </collision>
  <visual name="link_pipe_2_visual">
    <geometry>
      <mesh>
        <uri>model://tsduav_t4_link/meshes/link_pipe.STL</uri>
      </mesh>
    </geometry>
    <material>
      <script>
        <name>Gazebo/Green</name>
      </script>
    </material>
  </visual>
</link>
<joint name='link_pipe_2_joint' type="revolute">
  <parent>link_base</parent>
  <child>link_pipe_2</child>
  <axis>
    <xyz>0 1 0</xyz>
    <limit>
      <lower>-1.5707963267948966</lower>
      <upper>1.5707963267948966</upper>
    </limit>
    <dynamics>
      <damping>0.00001</damping>
    </dynamics>
    <use_parent_model_frame>1</use_parent_model_frame>
  </axis>
</joint>
</model>
</sdf>
