<?xml version="1.0" ?>
  
  <sdf version="1.5">
    <model name="uni350_multi">
      
      <include>
        <uri>model://uni350_multi_base</uri>
        <name>uni350_multi_base</name>
        <pose>0 0 0.0 0 0 0</pose>
      </include>
      <include>
        <uri>model://uni350_multi_prop</uri>
        <name>uni350_multi_prop_0</name>
        <pose>0.12854 -0.12889 0.0512 0 0 0</pose>
      </include>
      <include>
        <uri>model://uni350_multi_prop</uri>
        <name>uni350_multi_prop_1</name>
        <pose>-0.12854 -0.12889 0.0512 0 0 0</pose>
      </include>
      <include>
        <uri>model://uni350_multi_prop</uri>
        <name>uni350_multi_prop_2</name>
        <pose>-0.12854 0.12889 0.0512 0 0 3.141592653589793</pose>
      </include>
      <include>
        <uri>model://uni350_multi_prop</uri>
        <name>uni350_multi_prop_3</name>
        <pose>0.12854 0.12889 0.0512 0 0 3.141592653589793</pose>
      </include>
      
      <joint name="uni350_multi_prop_0_joint" type="revolute">
        <parent>uni350_multi_base::platform_base</parent>
        <child>uni350_multi_prop_0::prop </child>
        <axis>
          <xyz>0 0 1</xyz>
          <limit>
            <lower>-1e+16</lower>
            <upper>1e+16</upper>
          </limit>
          <dynamics>
            <damping>0.00001</damping>
          </dynamics>
          <use_parent_model_frame>1</use_parent_model_frame>
        </axis>
      </joint>
      
    
      <joint name="uni350_multi_prop_1_joint" type="revolute">
        <parent>uni350_multi_base::platform_base</parent>
        <child>uni350_multi_prop_1::prop </child>
        <axis>
          <xyz>0 0 1</xyz>
          <limit>
            <lower>-1e+16</lower>
            <upper>1e+16</upper>
          </limit>
          <dynamics>
            <damping>0.00001</damping>
          </dynamics>
          <use_parent_model_frame>1</use_parent_model_frame>
        </axis>
      </joint>
      
    
      <joint name="uni350_multi_prop_2_joint" type="revolute">
        <parent>uni350_multi_base::platform_base</parent>
        <child>uni350_multi_prop_2::prop </child>
        <axis>
          <xyz>0 0 1</xyz>
          <limit>
            <lower>-1e+16</lower>
            <upper>1e+16</upper>
          </limit>
          <dynamics>
            <damping>0.00001</damping>
          </dynamics>
          <use_parent_model_frame>1</use_parent_model_frame>
        </axis>
      </joint>
      
    
      <joint name="uni350_multi_prop_3_joint" type="revolute">
        <parent>uni350_multi_base::platform_base</parent>
        <child>uni350_multi_prop_3::prop </child>
        <axis>
          <xyz>0 0 1</xyz>
          <limit>
            <lower>-1e+16</lower>
            <upper>1e+16</upper>
          </limit>
          <dynamics>
            <damping>0.00001</damping>
          </dynamics>
          <use_parent_model_frame>1</use_parent_model_frame>
        </axis>
      </joint>
      
    
  </model>
  
</sdf>
